<?xml version="1.0"?>
  <robot name="rover">

    <link name="LinkFirstAxis">
      <inertial>
        <origin xyz="0 0 0" rpy="0 0 0"/>
        <mass value="1"/>
        <inertia ixx="10" ixy="10" ixz="10" iyy="10" iyz="10" izz="10"/>
      </inertial>
      <visual>
        <origin xyz="0 0 0" rpy="0 3.14159 0"/>
        <geometry>
          <box size="0.05499 0.1206 1.3267"/>
        </geometry>
      </visual>
      <collision name="FirstAxis">
        <origin xyz="0 0 0" rpy="0 3.14159 0"/>
        <geometry>
          <box size="0.05499 0.1206 1.3267"/>
        </geometry>
      </collision>
    </link>

    <link name="LinkFirstCylinder">
      <inertial>
        <origin xyz="0 0 0" rpy="0 0 0"/>
        <mass value="1"/>
        <inertia ixx="10" ixy="10" ixz="10" iyy="10" iyz="10" izz="10"/>
      </inertial>
      <visual>
        <origin xyz="0 0 0" rpy="0 0 0"/>
        <geometry>
          <cylinder radius="0.17273" length="0.07044"/>
        </geometry>
      </visual>
    </link>

    <link name="LinkMainTool">
      <inertial>
        <origin xyz="0 0 0" rpy="0 0 0"/>
        <mass value="1"/>
        <inertia ixx="10" ixy="10" ixz="10" iyy="10" iyz="10" izz="10"/>
      </inertial>
      <visual>
        <origin xyz="0 -0.4457 0.43202" rpy="1.5708 0 0"/>
        <geometry>
          <box size="0.11162 0.79854 0.07285"/>
        </geometry>
      </visual>
      <visual>
        <origin xyz="0 0 0" rpy="0 0 0"/>
        <geometry>
          <box size="0.11162 0.96219 0.07285"/>
        </geometry>
      </visual>
      <collision name="FixedTool">
        <origin xyz="0 -0.4457 0.43202" rpy="1.5708 0 0"/>
        <geometry>
          <box size="0.11162 0.79854 0.07285"/>
        </geometry>
      </collision>
      <collision name="MainTool">
        <origin xyz="0 0 0" rpy="0 0 0"/>
        <geometry>
          <box size="0.11162 0.96219 0.07285"/>
        </geometry>
      </collision>
    </link>

    <link name="LinkPrismaticTool">
      <inertial>
        <origin xyz="0 0 0" rpy="0 0 0"/>
        <mass value="1"/>
        <inertia ixx="10" ixy="10" ixz="10" iyy="10" iyz="10" izz="10"/>
      </inertial>
      <visual>
        <origin xyz="0 0 0" rpy="0 0 0"/>
        <geometry>
          <box size="0.11162 0.79854 0.07285"/>
        </geometry>
      </visual>
      <collision name="PrismaticTool">
        <origin xyz="0 0 0" rpy="0 0 0"/>
        <geometry>
          <box size="0.11162 0.79854 0.07285"/>
        </geometry>
      </collision>
    </link>

    <link name="LinkSecondAxis">
      <inertial>
        <origin xyz="0 0 0" rpy="0 0 0"/>
        <mass value="1"/>
        <inertia ixx="10" ixy="10" ixz="10" iyy="10" iyz="10" izz="10"/>
      </inertial>
      <visual>
        <origin xyz="0 0 0" rpy="0 3.14159 0"/>
        <geometry>
          <box size="0.02784 0.09213 1.15343"/>
        </geometry>
      </visual>
      <collision name="SecondAxis">
        <origin xyz="0 0 0" rpy="0 3.14159 0"/>
        <geometry>
          <box size="0.02784 0.09213 1.15343"/>
        </geometry>
      </collision>
    </link>

    <link name="LinkSecondCylinder">
      <inertial>
        <origin xyz="0 0 0" rpy="0 0 0"/>
        <mass value="1"/>
        <inertia ixx="10" ixy="10" ixz="10" iyy="10" iyz="10" izz="10"/>
      </inertial>
      <visual>
        <origin xyz="0 0 0" rpy="0 0 0"/>
        <geometry>
          <cylinder radius="0.09296" length="0.03791"/>
        </geometry>
      </visual>
    </link>

    <link name="LinkWheelBackLeft">
      <inertial>
        <origin xyz="0 0 0" rpy="0 0 0"/>
        <mass value="50"/>
        <inertia ixx="10" ixy="10" ixz="10" iyy="10" iyz="10" izz="10"/>
      </inertial>
      <visual>
        <origin xyz="0 0 0" rpy="0 0 0"/>
        <geometry>
          <cylinder radius="0.47719" length="0.23635"/>
        </geometry>
      </visual>
      <collision name="WheelBackLeft">
        <origin xyz="0 0 0" rpy="0 0 0"/>
        <geometry>
          <cylinder radius="0.47719" length="0.23635"/>
        </geometry>
      </collision>
    </link>

    <link name="LinkWheelBackRight">
      <inertial>
        <origin xyz="0 0 0" rpy="0 0 0"/>
        <mass value="50"/>
        <inertia ixx="10" ixy="10" ixz="10" iyy="10" iyz="10" izz="10"/>
      </inertial>
      <visual>
        <origin xyz="0 0 0" rpy="0 0 0"/>
        <geometry>
          <cylinder radius="0.47719" length="0.23635"/>
        </geometry>
      </visual>
      <collision name="WheelBackRight">
        <origin xyz="0 0 0" rpy="0 0 0"/>
        <geometry>
          <cylinder radius="0.47719" length="0.23635"/>
        </geometry>
      </collision>
    </link>

    <link name="LinkWheelFrontLeft">
      <inertial>
        <origin xyz="0 0 0" rpy="0 0 0"/>
        <mass value="50"/>
        <inertia ixx="10" ixy="10" ixz="10" iyy="10" iyz="10" izz="10"/>
      </inertial>
      <visual>
        <origin xyz="0 0 0" rpy="0 0 0"/>
        <geometry>
          <cylinder radius="0.47719" length="0.23635"/>
        </geometry>
      </visual>
      <collision name="WheelFrontLeft">
        <origin xyz="0 0 0" rpy="0 0 0"/>
        <geometry>
          <cylinder radius="0.47719" length="0.23635"/>
        </geometry>
      </collision>
    </link>

    <link name="LinkWheelFrontRight">
      <inertial>
        <origin xyz="0 0 0" rpy="0 0 0"/>
        <mass value="50"/>
        <inertia ixx="10" ixy="10" ixz="10" iyy="10" iyz="10" izz="10"/>
      </inertial>
      <visual>
        <origin xyz="0 0 0" rpy="0 0 0"/>
        <geometry>
          <cylinder radius="0.47719" length="0.23635"/>
        </geometry>
      </visual>
      <collision name="WheelFrontRight">
        <origin xyz="0 0 0" rpy="0 0 0"/>
        <geometry>
          <cylinder radius="0.47719" length="0.23635"/>
        </geometry>
      </collision>
    </link>

    <link name="MainLink">
      <inertial>
        <origin xyz="0 0 0" rpy="0 0 0"/>
        <mass value="80.0"/>
        <inertia ixx="10" ixy="10" ixz="10" iyy="10" iyz="10" izz="10"/>
      </inertial>
      <visual>
        <origin xyz="0 0 0" rpy="0 0 0"/>
        <geometry>
          <box size="3.79233 2.0 1.28901"/>
        </geometry>
      </visual>
      <visual>
        <origin xyz="-1.87213 0 0.82748" rpy="0 0 1.5708"/>
        <geometry>
          <box size="1.92416 0.0425 0.38178"/>
        </geometry>
      </visual>
      <visual>
        <origin xyz="-0.3584 0.98504 0.82748" rpy="0 0 0"/>
        <geometry>
          <box size="3.06457 0.0425 0.38178"/>
        </geometry>
      </visual>
      <visual>
        <origin xyz="-0.3584 -0.97745 0.82748" rpy="0 0 0"/>
        <geometry>
          <box size="3.06457 0.0425 0.38178"/>
        </geometry>
      </visual>
      <collision name="MainCube">
        <origin xyz="0 0 0" rpy="0 0 0"/>
        <geometry>
          <box size="3.79233 2.0 1.28901"/>
        </geometry>
      </collision>
      <collision name="MiniBoxBack">
        <origin xyz="-1.87213 0 0.82748" rpy="0 0 1.5708"/>
        <geometry>
          <box size="1.92416 0.0425 0.38178"/>
        </geometry>
      </collision>
      <collision name="MiniBoxLeft">
        <origin xyz="-0.3584 0.98504 0.82748" rpy="0 0 0"/>
        <geometry>
          <box size="3.06457 0.0425 0.38178"/>
        </geometry>
      </collision>
      <collision name="MiniBoxRight">
        <origin xyz="-0.3584 -0.97745 0.82748" rpy="0 0 0"/>
        <geometry>
          <box size="3.06457 0.0425 0.38178"/>
        </geometry>
      </collision>
    </link>

    <link name="CameraLink">
      <inertial>
        <origin xyz="0 0 0" rpy="0 0 0"/>
        <mass value="1.0"/>
        <inertia ixx="10" ixy="10" ixz="10" iyy="10" iyz="10" izz="10"/>
      </inertial>
      <visual>
        <origin xyz="0 0 0" rpy="0 0 0"/>
        <geometry>
          <box size="0.2 0.2 0.2"/>
        </geometry>
      </visual>
      <collision name="collision">
        <origin xyz="0 0 0" rpy="0 0 0"/>
        <geometry>
          <box size="0.2 0.2 0.2"/>
        </geometry>
      </collision>
    </link>

    <link name="CameraToolLink">
      <visual>
        <origin xyz="0 0 0" rpy="0 0 0"/>
        <geometry>
          <box size="0.1 0.1 0.1"/>
        </geometry>
      </visual>
    </link>

   <joint name="JointFirstAxis" type="continuous">
      <origin xyz="0.30496 -0.00153 0.57386" rpy="0 -0.55364 -3.14159"/>
      <parent link="LinkFirstCylinder"/>
      <child link="LinkFirstAxis"/>
      <axis xyz="0 0 1.0"/>
    </joint>

    <joint name="JointFirstCylinder" type="continuous">
      <origin xyz="1.72438 0.01793 0.67942" rpy="0 0 0"/>
      <parent link="MainLink"/>
      <child link="LinkFirstCylinder"/>
      <axis xyz="0 -0.99528 -0.09705"/>
    </joint>

    <joint name="JointMainTool" type="continuous">
      <origin xyz="0.00634 0.0044 -0.59229" rpy="0 2.62128 0"/>
      <parent link="LinkSecondAxis"/>
      <child link="LinkMainTool"/>
      <axis xyz="0.06699 -0.99767 0.01285"/>
    </joint>

    <joint name="JointPrismaticTool" type="prismatic">
      <origin xyz="0 0.44383 0.43202" rpy="1.5708 0 0"/>
      <parent link="LinkMainTool"/>
      <child link="LinkPrismaticTool"/>
      <axis xyz="0 0 1.0"/>
      <limit lower="0" upper="0.5" effort="10" velocity="10"/>
    </joint>

    <joint name="JointSecondAxis" type="continuous">
      <origin xyz="0.54297 0.00247 -0.25169" rpy="0 1.07395 -3.14159"/>
      <parent link="LinkSecondCylinder"/>
      <child link="LinkSecondAxis"/>
      <axis xyz="-0.21236 0.04177 -0.9763"/>
    </joint>

    <joint name="JointSecondCylinder" type="continuous">
      <origin xyz="-0.05158 -0.00153 0.67936" rpy="0 0 3.14159"/>
      <parent link="LinkFirstAxis"/>
      <child link="LinkSecondCylinder"/>
      <axis xyz="0 0 1.0"/>
    </joint>

    <joint name="joint_camera" type="fixed">
      <origin xyz="1.8 0.5 0.75" rpy="0 0 0"/>
      <parent link="MainLink"/>
      <child link="CameraLink"/>
      <axis xyz="0 0 1.0"/>
    </joint>

    <joint name="joint_camera_tool" type="fixed">
      <origin xyz="0 0 0" rpy="0 -90 0"/>
      <parent link="LinkMainTool"/>
      <child link="CameraToolLink"/>
      <axis xyz="0 0 1.0"/>
    </joint>

    <joint name="joint_wheel_back_left" type="continuous">
      <origin xyz="-1.23386 1.1772 -0.46428" rpy="1.5708 0 0"/>
      <parent link="MainLink"/>
      <child link="LinkWheelBackLeft"/>
      <axis xyz="0 0 -1.0"/>
    </joint>

    <joint name="joint_wheel_back_right" type="continuous">
      <origin xyz="-1.20753 -1.15931 -0.46427" rpy="1.5708 0 0"/>
      <parent link="MainLink"/>
      <child link="LinkWheelBackRight"/>
      <axis xyz="0 0 -1.0"/>
    </joint>

    <joint name="joint_wheel_front_left" type="continuous">
      <origin xyz="1.19673 1.1772 -0.46427" rpy="1.5708 0 0"/>
      <parent link="MainLink"/>
      <child link="LinkWheelFrontLeft"/>
      <axis xyz="0 0 -1.0"/>
    </joint>

    <joint name="joint_wheel_front_right" type="continuous">
      <origin xyz="1.19673 -1.15931 -0.46427" rpy="1.5708 0 0"/>
      <parent link="MainLink"/>
      <child link="LinkWheelFrontRight"/>
      <axis xyz="0 0 -1.0"/>
    </joint>

    <gazebo>
      <plugin name="gazebo_ros_control" filename="libgazebo_ros_control.so">
        <robotNamespace>/rover</robotNamespace>
      </plugin>
    </gazebo>

    <gazebo reference="CameraLink">
      <sensor name='cam_sensor' type='camera'>
        <pose>1.8 0.5 0.75 0 0 0</pose>
        <update_rate>20.000000</update_rate>
        <camera name='CameraLink'>
          <horizontal_fov>1.570000</horizontal_fov>
          <image>
            <width>320</width>
            <height>240</height>
            <format>R8G8B8</format>
          </image>
          <clip>
            <near>0.100000</near>
            <far>15.000000</far>
          </clip>
        </camera>
        <plugin name="camera_controller" filename="libgazebo_ros_camera.so">
          <alwaysOn>true</alwaysOn>
          <updateRate>0.0</updateRate>
          <cameraName>camera</cameraName>
          <imageTopicName>image_raw</imageTopicName>
          <cameraInfoTopicName>camera_info</cameraInfoTopicName>
          <frameName>camera_top_body</frameName>
          <hackBaseline>0.07</hackBaseline>
          <distortionK1>0.0</distortionK1>
          <distortionK2>0.0</distortionK2>
          <distortionK3>0.0</distortionK3>
          <distortionT1>0.0</distortionT1>
          <distortionT2>0.0</distortionT2>
        </plugin>
      </sensor>
    </gazebo>

    <gazebo reference="CameraToolLink">
      <sensor name='cam_sensor' type='camera'>
        <pose>1.8 0.5 5 0 0 0</pose>
        <update_rate>20.000000</update_rate>
        <camera name='CameraToolLink'>
          <horizontal_fov>1.570000</horizontal_fov>
          <image>
            <width>320</width>
            <height>240</height>
            <format>R8G8B8</format>
          </image>
          <clip>
            <near>0.100000</near>
            <far>15.000000</far>
          </clip>
        </camera>
        <plugin name="camera_controller" filename="libgazebo_ros_camera.so">
          <alwaysOn>true</alwaysOn>
          <updateRate>0.0</updateRate>
          <cameraName>camera_tool</cameraName>
          <imageTopicName>image_raw</imageTopicName>
          <cameraInfoTopicName>camera_info</cameraInfoTopicName>
          <frameName>camera_top_body</frameName>
          <hackBaseline>0.07</hackBaseline>
          <distortionK1>0.0</distortionK1>
          <distortionK2>0.0</distortionK2>
          <distortionK3>0.0</distortionK3>
          <distortionT1>0.0</distortionT1>
          <distortionT2>0.0</distortionT2>
        </plugin>
      </sensor>
    </gazebo>

    <transmission name="joint_wheel_front_right_trans">
      <type>transmission_interface/SimpleTransmission</type>
      <actuator name="motor1">
        <mechanicalReduction>1</mechanicalReduction>
      </actuator>
      <joint name="joint_wheel_front_right">
        <hardwareInterface>hardware_interface/VelocityJointInterface</hardwareInterface>
      </joint>
    </transmission>

    <transmission name="joint_wheel_front_left_trans">
      <type>transmission_interface/SimpleTransmission</type>
      <actuator name="motor2">
        <mechanicalReduction>1</mechanicalReduction>
        <hardwareInterface>hardware_interface/VelocityJointInterface</hardwareInterface>
      </actuator>
      <joint name="joint_wheel_front_left">
        <hardwareInterface>hardware_interface/VelocityJointInterface</hardwareInterface>
      </joint>
    </transmission>

    <transmission name="joint_wheel_back_right_trans">
      <type>transmission_interface/SimpleTransmission</type>
      <actuator name="motor3">
        <mechanicalReduction>1</mechanicalReduction>
        <hardwareInterface>hardware_interface/VelocityJointInterface</hardwareInterface>
      </actuator>
      <joint name="joint_wheel_back_right">
        <hardwareInterface>hardware_interface/VelocityJointInterface</hardwareInterface>
      </joint>
    </transmission>

    <transmission name="joint_wheel_back_left_trans">
      <type>transmission_interface/SimpleTransmission</type>
      <actuator name="motor4">
        <mechanicalReduction>1</mechanicalReduction>
        <hardwareInterface>hardware_interface/VelocityJointInterface</hardwareInterface>
      </actuator>
      <joint name="joint_wheel_back_left">
        <hardwareInterface>hardware_interface/VelocityJointInterface</hardwareInterface>
      </joint>
    </transmission>

    <transmission name="joint_first_axis_trans">
      <type>transmission_interface/SimpleTransmission</type>
      <actuator name="motor5">
        <mechanicalReduction>1</mechanicalReduction>
        <hardwareInterface>hardware_interface/VelocityJointInterface</hardwareInterface>
      </actuator>
      <joint name="JointFirstAxis">
        <hardwareInterface>hardware_interface/VelocityJointInterface</hardwareInterface>
      </joint>
    </transmission>

    <transmission name="joint_first_cylinder_trans">
      <type>transmission_interface/SimpleTransmission</type>
      <actuator name="motor5">
        <mechanicalReduction>1</mechanicalReduction>
        <hardwareInterface>hardware_interface/VelocityJointInterface</hardwareInterface>
      </actuator>
      <joint name="JointFirstCylinder">
        <hardwareInterface>hardware_interface/VelocityJointInterface</hardwareInterface>
      </joint>
    </transmission>

    <transmission name=" joint_main_tool_trans">
      <type>transmission_interface/SimpleTransmission</type>
      <actuator name="motor6">
        <mechanicalReduction>1</mechanicalReduction>
        <hardwareInterface>hardware_interface/VelocityJointInterface</hardwareInterface>
      </actuator>
      <joint name="JointMainTool">
        <hardwareInterface>hardware_interface/VelocityJointInterface</hardwareInterface>
      </joint>
    </transmission>

    <transmission name="joint_prismatic_tool_trans">
      <type>transmission_interface/SimpleTransmission</type>
      <actuator name="motor7">
        <mechanicalReduction>1</mechanicalReduction>
        <hardwareInterface>hardware_interface/VelocityJointInterface</hardwareInterface>
      </actuator>
      <joint name="JointPrismaticTool">
        <hardwareInterface>hardware_interface/VelocityJointInterface</hardwareInterface>
      </joint>
    </transmission>

    <transmission name="joint_second_axis_trans">
      <type>transmission_interface/SimpleTransmission</type>
      <actuator name="motor8">
        <mechanicalReduction>1</mechanicalReduction>
        <hardwareInterface>hardware_interface/VelocityJointInterface</hardwareInterface>
      </actuator>
      <joint name="JointSecondAxis">
        <hardwareInterface>hardware_interface/VelocityJointInterface</hardwareInterface>
      </joint>
    </transmission>

    <transmission name="joint_second_cylinder_trans">
      <type>transmission_interface/SimpleTransmission</type>
      <actuator name="motor9">
        <mechanicalReduction>1</mechanicalReduction>
        <hardwareInterface>hardware_interface/VelocityJointInterface</hardwareInterface>
      </actuator>
      <joint name="JointSecondCylinder">
        <hardwareInterface>hardware_interface/VelocityJointInterface</hardwareInterface>
      </joint>
    </transmission>

    <gazebo reference="MainLink">
      <material>Gazebo/Red</material>
    </gazebo>

    <gazebo reference="LinkFirstAxis">
      <material>Gazebo/Gray</material>
    </gazebo>

    <gazebo reference="LinkFirstCylinder">
      <material>Gazebo/Gray</material>
    </gazebo>

    <gazebo reference="LinkMainTool">
      <material>Gazebo/Gray</material>
    </gazebo>

    <gazebo reference="LinkPrismaticTool">
      <material>Gazebo/Gray</material>
    </gazebo>

    <gazebo reference="LinkSecondAxis">
      <material>Gazebo/Gray</material>
    </gazebo>

    <gazebo reference="LinkSecondCylinder">
      <material>Gazebo/Gray</material>
    </gazebo>

    <gazebo reference="LinkWheelFrontRight">
      <material>Gazebo/Black</material>
    </gazebo>

    <gazebo reference="LinkWheelFrontLeft">
      <material>Gazebo/Black</material>
    </gazebo>

    <gazebo reference="LinkWheelBackRight">
      <material>Gazebo/Black</material>
    </gazebo>

    <gazebo reference="LinkWheelBackLeft">
      <material>Gazebo/Black</material>
    </gazebo>

    <gazebo reference="CameraLink">
      <material>Gazebo/Green</material>
    </gazebo>

    <gazebo reference="CameraToolLink">
      <material>Gazebo/Blue</material>
    </gazebo>

  </robot>
